Workbook

Sheet 概要
A1: ショッピングサイト 要件定義書
A2: ウェブカツ オリジナルアウトプット。各シートの内容は、機能要件一覧のIDで対応しています。
A4: 1. プロジェクト概要
A5: プロジェクト名 | B5: ショッピングサイト(ウェブカツ オリジナルアウトプット)
A6: 目的 | B6: 出品者が複数いるショッピングサイトをLaravelで作り、AWSで公開する。ポートフォリオとして提示できる状態にする。
A7: 利用者 | B7: 購入者(ゲスト・会員)、出品者(商品を登録する会員)。購入者と出品者は、連絡掲示板で商品についてやり取りできる
A8: 教材との関係 | B8: ウェブカツ WEBサービス部のレッスン(Lesson 02〜25)を順に進めながら作る。教材にない機能(カート・注文確定・注文履歴)は、Lesson 25のあとに作る
A9: スコープの区分 | B9: Phase1:AWSで公開するまでに作る機能(教材のレッスンで作る機能+連絡掲示板+カート・注文確定)/ Phase2:公開後に追加する機能(注文履歴)/ 対象外:今回は作らない機能
A10: 今回作らないもの | B10: クレジットカード決済、在庫管理、メール通知、レビュー機能
A11: 技術構成 | B11: Laravel 13 / PHP 8.3以上(ローカルはMAMPのPHP 8.4.1)/ MySQL(ローカルはMAMP)/ 本番はAWS(EC2 + RDSを想定。インフラ部の構成に合わせて確定)
A12: ソース管理 | B12: Git + GitHub(private)。機能ごとにfeatureブランチを切り、動作確認後にmainへマージする
A13: 体制・稼働 | B13: 個人開発(1名)。稼働時間は平日4.5時間・休日10時間。うち平日1時間・休日2時間は再現練習に充て、残りを開発に使う(日程の計算前提。稼働カレンダーで変更可)
A14: 学習の進め方 | B14: 教材なしで作れるようになるため、機能ごとに ①写経(教材どおりに作る)②再現(翌日、教材を見ずに練習用ブランチで作り直す)③改造(教材にない変化を1つ足す)④白紙(週末に、同じ型の機能を別の題材で作る)の順で身につける。教材にない機能(カート・注文確定・注文履歴)は、ヒントだけをもらって自力で実装する。到達目標:教材を見ずにCRUDを2時間以内で作れる
A15: 参考資料 | B15: ウェブカツ WEBサービス部 Lesson 01「WEBサービスと必要な機能」の17機能、Lesson 23「連絡掲示板機能」
A17: 2. 進捗サマリ(各シートから自動集計)
A18: Phase1の機能数 | B18: =COUNTIF(機能要件一覧!$G$5:$G$28,"Phase1") -> 18
A19: 完了 | B19: =COUNTIFS(機能要件一覧!$G$5:$G$28,"Phase1",機能要件一覧!$L$5:$L$28,"完了") -> 0
A20: 作業中 | B20: =COUNTIFS(機能要件一覧!$G$5:$G$28,"Phase1",機能要件一覧!$L$5:$L$28,"作業中") -> 0
A21: 未着手 | B21: =COUNTIFS(機能要件一覧!$G$5:$G$28,"Phase1",機能要件一覧!$L$5:$L$28,"未着手") -> 18
A22: Phase1の進捗率(完了 ÷ Phase1の機能数) | B22: =IF(B18=0,0,B19/B18) -> 0
A23: Phase2の機能数 | B23: =COUNTIF(機能要件一覧!$G$5:$G$28,"Phase2") -> 1
A24: 対象外の機能数 | B24: =COUNTIF(機能要件一覧!$G$5:$G$28,"対象外") -> 5
A25: 教材の17機能のカバー数 | B25: =SUMPRODUCT(--ISNUMBER(--LEFT(機能要件一覧!$H$5:$H$28,1)))&" / 17" -> 17 / 17
A26: 教材レッスンが「要確認」の機能数 | B26: =COUNTIF(機能要件一覧!$I$5:$I$28,"要確認") -> 7
A27: 未決の確認事項 | B27: =COUNTIF(課題・確認事項!$G$5:$G$16,"未決") -> 6
A28: AWS公開の予定日 | B28: =スケジュール!M23 -> 46335
A29: Phase1完了の予定日 | B29: =スケジュール!M24 -> 46337
A30: Phase2完了の予定日 | B30: =スケジュール!M25 -> 46339
A31: 残りの合計見積(予備込み・h) | B31: =スケジュール!J26 -> 108.6
A33: 3. 更新履歴
A34: 0.5(2026/10/26) | B34: テーブル定義を、Lesson 06 で作成したマイグレーションの内容に更新(categories・message_boards を追加、日時と削除フラグを timestamps()・softDeletes() に、外部キーを foreignId()->constrained() で作成)。「マイグレーション」列を追加し、作成済み/未作成(カート・注文)を区別。会員をroleで分けない形に決定し、出品者専用の登録(F-009)を対象外に。在庫は1点もの(フリマ型)として扱うことに決定(Q-004)
A35: 0.4(2026/10/21) | B35: フルスクラッチ練習の方針を追加(学習の進め方)。稼働カレンダーに再現練習の時間を追加し、開発に使う時間で日程を再計算。起算日を2026/10/22に変更。Lesson 01〜06の状況を更新
A36: 0.3(2026/10/17) | B36: 連絡掲示板(Lesson 23)を追加(F-024、画面S-018〜S-020、messagesテーブル、Q-011)。教材レッスンの列を追加し、スケジュールを教材のレッスン順に組み替え。教材の内容に合わせて、プロフィール・パスワード系・お気に入りなどをPhase1に移動
A37: 0.2(2026/10/16) | B37: 出品者が複数いる前提に変更(Q-001決定)。出品者向けの画面・テーブル・非機能要件を追加。見積工数と稼働カレンダーによる日程を追加
A38: 0.1(2026/10/16) | B38: 初版。教材の17機能との対応を含めて作成

Sheet 機能要件一覧
A1: 機能要件一覧
A2: 黄色のセルが編集用です。「教材の機能」はLesson 01の17機能との対応、「教材レッスン」は作るときに見るレッスンです。「要確認」は、Lesson 12〜14などの内容が分かった時点で更新します。
A4: 機能ID | B4: 大分類 | C4: 機能名 | D4: 機能概要 | E4: 利用者 | F4: 優先度 | G4: フェーズ | H4: 教材の機能 | I4: 教材レッスン | J4: 受入条件 | K4: 想定ブランチ | L4: 状況 | M4: 備考
A5: F-001 | B5: 会員管理 | C5: ユーザー登録 | D5: メールアドレスとパスワードで会員登録する | E5: ゲスト | F5: 高 | G5: Phase1 | H5: 1. ユーザー登録 | I5: Lesson 09〜10 | J5: 名前・メール・パスワードを入力して登録でき、登録後にログイン状態になる。メールの重複や入力不備ではエラーが表示される。 | K5: feature/auth | L5: 未着手 | M5: 認証の実装方法はQ-005で決定
A6: F-002 | B6: 会員管理 | C6: ログイン | D6: 登録済みのメールアドレスとパスワードでログインする | E6: ゲスト | F6: 高 | G6: Phase1 | H6: 2. ログイン | I6: Lesson 11 | J6: 正しい入力でログインでき、誤った入力ではエラーが表示される。 | K6: feature/auth | L6: 未着手
A7: F-003 | B7: 会員管理 | C7: ログアウト | D7: ログイン中の会員がログアウトする | E7: 会員 | F7: 高 | G7: Phase1 | H7: 3. ログアウト | I7: 要確認 | J7: ログアウト後は、会員専用の画面(カート・注文)に入れない。 | K7: feature/auth | L7: 未着手 | M7: Lesson 12〜14のどれかに入っている想定
A8: F-004 | B8: 会員管理 | C8: プロフィール登録 | D8: 住所・電話番号など、名前以外の会員情報を登録する | E8: 会員 | F8: 中 | G8: Phase1 | H8: 5. プロフィール登録 | I8: 要確認 | J8: 入力した内容が保存され、あとから確認できる。 | K8: feature/profile | L8: 未着手 | M8: 配送先の扱いはQ-003で決定
A9: F-005 | B9: 会員管理 | C9: プロフィール編集 | D9: 登録したプロフィールを変更する | E9: 会員 | F9: 中 | G9: Phase1 | H9: 6. プロフィール編集 | I9: 要確認 | J9: 変更した内容が保存され、画面に反映される。 | K9: feature/profile | L9: 未着手
A10: F-006 | B10: 会員管理 | C10: パスワード変更 | D10: ログイン中にパスワードを変更する | E10: 会員 | F10: 低 | G10: Phase1 | H10: 7. パスワード変更 | I10: Lesson 15 | J10: 現在のパスワードを入力して変更でき、変更後は新しいパスワードでログインできる。 | K10: feature/password | L10: 未着手
A11: F-007 | B11: 会員管理 | C11: パスワードリマインダー | D11: パスワードを忘れたときに再設定する | E11: ゲスト | F11: 低 | G11: Phase1 | H11: 8. パスワードリマインダー | I11: Lesson 16 | J11: 登録メールアドレス宛の案内から、パスワードを再設定できる。 | K11: feature/password | L11: 未着手 | M11: メール送信が必要。F-022(メール通知)は対象外だが、再設定メールの送信だけは別に必要(Q-008)
A12: F-008 | B12: 会員管理 | C12: 退会 | D12: 会員が自分のアカウントを削除(退会)する | E12: 会員 | F12: 低 | G12: Phase1 | H12: 4. 退会 | I12: 要確認 | J12: 退会後は、そのアカウントでログインできない。 | K12: feature/withdraw | L12: 未着手 | M12: 注文履歴の扱い(残す/消す)を決める必要あり
A13: F-009 | B13: 出品者機能 | C13: 販売側ユーザー登録 | D13: 出品者として登録する | E13: ゲスト | F13: 高 | G13: 対象外 | H13: 9. 販売側ユーザー登録 | I13: 要確認 | J13: 出品者として登録でき、出品者向けの画面を使える。 | K13: feature/seller | L13: 対象外 | M13: 会員はroleで分けず、会員登録した人は誰でも出品できるため、出品者専用の登録は作らない(Q-001)
A14: F-010 | B14: 商品 | C14: 商品一覧表示 | D14: 商品を一覧で表示する | E14: ゲスト/会員 | F14: 高 | G14: Phase1 | H14: 14. コンテンツ一覧表示 | I14: Lesson 20 | J14: 商品の名前と価格が表示される。件数が多い場合はページ分割される。 | K14: feature/product-list | L14: 未着手 | M14: 教材順では商品登録の後に作るため、表示するデータは商品登録で用意する(Q-009)
A15: F-011 | B15: 商品 | C15: 商品詳細表示 | D15: 1つの商品の説明・価格を表示し、カートに入れる | E15: ゲスト/会員 | F15: 高 | G15: Phase1 | H15: 15. コンテンツ詳細表示 | I15: Lesson 21 | J15: 一覧から選ぶと、商品名・説明・価格と「カートに入れる」ボタンが表示される。 | K15: feature/product-detail | L15: 未着手
A16: F-012 | B16: 商品 | C16: 商品検索 | D16: キーワードで商品を絞り込む | E16: ゲスト/会員 | F16: 中 | G16: Phase1 | H16: 16. コンテンツ検索 | I16: Lesson 22 | J16: キーワードに一致する商品だけが表示される。一致がない場合はその旨が表示される。 | K16: feature/search | L16: 未着手
A17: F-013 | B17: 商品 | C17: お気に入り登録 | D17: 気に入った商品を登録し、一覧で見る | E17: 会員 | F17: 低 | G17: Phase1 | H17: 17. お気に入り登録 | I17: Lesson 24 | J17: 商品をお気に入りに追加・解除でき、お気に入り一覧で確認できる。 | K17: feature/favorites | L17: 未着手
A18: F-014 | B18: カート・注文 | C18: カート | D18: 商品をカートに入れ、削除する(1点ものなので数量は常に1) | E18: 会員 | F18: 高 | G18: Phase1 | H18: (教材外) | I18: - | J18: 商品を追加でき、数量の変更と削除ができる。合計金額が正しく表示される。 | K18: feature/cart | L18: 未着手 | M18: 未ログイン時はログイン画面へ誘導(案)。教材にない部分なのでLesson 25のあとに作る
A19: F-015 | B19: カート・注文 | C19: 注文確定(決済なし) | D19: カートの内容で注文を確定し、保存する | E19: 会員 | F19: 高 | G19: Phase1 | H19: (教材外) | I19: - | J19: 注文の明細と合計金額が保存され、完了画面が表示される。確定後はカートが空になる。 | K19: feature/order | L19: 未着手 | M19: 決済はF-017(対象外)。複数の出品者の商品を1回の注文に含められる(Q-010)
A20: F-016 | B20: カート・注文 | C20: 注文履歴表示 | D20: 自分の過去の注文を一覧・詳細で確認する | E20: 会員 | F20: 中 | G20: Phase2 | H20: (教材外) | I20: - | J20: 自分の注文だけが日付順に表示され、明細を確認できる。 | K20: feature/order-history | L20: 未着手 | M20: マイページ(Q-012)に入れる場合は、Phase1に移す
A21: F-017 | B21: カート・注文 | C21: 決済(クレジットカード) | D21: 外部の決済サービスと連携して支払う | E21: 会員 | F21: - | G21: 対象外 | H21: 10. 決済 | I21: - | L21: 対象外 | M21: 外部サービスとの連携が必要で工数が大きい。今回は注文確定までとする(Q-002)
A22: F-018 | B22: 出品者機能 | C22: 商品登録 | D22: 出品者が自分の商品を登録する | E22: 出品者 | F22: 高 | G22: Phase1 | H22: 11. コンテンツ登録 | I22: Lesson 17〜19 | J22: 入力した商品が保存され、商品一覧に表示される。入力不備ではエラーが表示される。 | K22: feature/product-register | L22: 未着手 | M22: 商品は登録した出品者に紐づく。画像の保存先はQ-006で決定
A23: F-019 | B23: 出品者機能 | C23: 商品編集 | D23: 出品者が自分の商品情報を編集する | E23: 出品者 | F23: 中 | G23: Phase1 | H23: 12. コンテンツ編集 | I23: 要確認 | J23: 自分の商品だけ編集でき、変更が一覧・詳細に反映される。他の出品者の商品は編集できない。 | K23: feature/product-register | L23: 未着手 | M23: Lesson 17〜19またはLesson 25に入っている想定
A24: F-020 | B24: 出品者機能 | C24: 商品削除 | D24: 出品者が自分の商品を削除する | E24: 出品者 | F24: 中 | G24: Phase1 | H24: 13. コンテンツ削除 | I24: 要確認 | J24: 自分の商品だけ削除でき、削除した商品は一覧に表示されなくなる。 | K24: feature/product-register | L24: 未着手 | M24: 注文済みの商品を削除した場合の扱いを決める
A25: F-021 | B25: その他 | C25: 在庫管理 | D25: 在庫数の管理、注文時の減算 | E25: 出品者 | F25: - | G25: 対象外 | H25: (教材外) | I25: - | L25: 対象外 | M25: 1点もの(フリマ型)として扱うため、在庫数は持たない(Q-004)
A26: F-022 | B26: その他 | C26: メール通知 | D26: 注文完了などのメールを送る | E26: 会員 | F26: - | G26: 対象外 | H26: (教材外) | I26: - | L26: 対象外 | M26: パスワード再設定メールの送信(F-007)は別に必要(Q-008)
A27: F-023 | B27: その他 | C27: レビュー機能 | D27: 商品へのレビュー投稿 | E27: 会員 | F27: - | G27: 対象外 | H27: (教材外) | I27: - | L27: 対象外
A28: F-024 | B28: 問い合わせ | C28: 連絡掲示板 | D28: 購入者が商品について出品者に問い合わせ、出品者が返信する | E28: 会員/出品者 | F28: 中 | G28: Phase1 | H28: (17機能外) | I28: Lesson 23 | J28: 購入者が商品詳細から出品者へメッセージを送れる。出品者は問い合わせ一覧から開いて返信できる。その商品の出品者と問い合わせた購入者以外は、やり取りを見られない。 | K28: feature/messages | L28: 未着手 | M28: 商品ごとの、購入者と出品者の1対1(案)。Lesson 23の内容に合わせて見直す(Q-011)

Sheet 非機能要件
A1: 非機能要件
A2: 黄色のセルが編集用です。「確度」が「案」のものは、決まり次第「確定」に変えてください。
A4: ID | B4: 区分 | C4: 要件 | D4: 対応方針 | E4: 確度 | F4: 備考
A5: NF-001 | B5: セキュリティ | C5: パスワードを平文で保存しない | D5: Laravelのハッシュ機能(標準)で保存する | E5: 確定
A6: NF-002 | B6: セキュリティ | C6: フォーム送信時のCSRF対策 | D6: Laravel標準の仕組みを、すべての送信フォームで有効にする | E6: 確定
A7: NF-003 | B7: セキュリティ | C7: SQLインジェクション対策 | D7: Eloquentまたはクエリビルダを使い、SQL文に入力値を直接埋め込まない | E7: 確定
A8: NF-004 | B8: セキュリティ | C8: 秘密情報の管理 | D8: .envをGit管理しない。本番用の.envはサーバー上で別に作成する | E8: 確定 | F8: DBパスワード、APP_KEYなど
A9: NF-005 | B9: セキュリティ | C9: 本番でのデバッグ表示の無効化 | D9: 本番は APP_ENV=production、APP_DEBUG=false にする | E9: 確定
A10: NF-006 | B10: セキュリティ | C10: 通信の暗号化 | D10: 公開時はHTTPS(独自ドメイン+証明書)で提供する | E10: 案 | F10: 公開構成(Q-007)に合わせて確定
A11: NF-007 | B11: 性能 | C11: 一覧の表示速度 | D11: 商品一覧はページ分割する(1ページあたりの件数は仮に12件) | E11: 案
A12: NF-008 | B12: 運用 | C12: DBのバックアップ | D12: 本番DBは自動バックアップを有効にする(RDSを使う場合) | E12: 案 | F12: Q-007の結果による
A13: NF-009 | B13: 運用 | C13: エラーの記録 | D13: Laravelのログ(storage/logs)にエラーを記録する | E13: 確定
A14: NF-010 | B14: 保守性 | C14: ブランチ運用 | D14: mainは常に動く状態を保つ。機能ごとにfeatureブランチを切り、動作確認後にマージする | E14: 確定
A15: NF-011 | B15: 保守性 | C15: 環境ごとの設定 | D15: 開発(ローカル)と本番の違いは.envで吸収する | E15: 確定
A16: NF-012 | B16: 保守性 | C16: 動作確認 | D16: 主要機能は、受入条件(機能要件一覧)に沿って動作を確認する | E16: 案 | F16: 自動テストの導入は余裕があれば
A17: NF-013 | B17: 互換性 | C17: 対応ブラウザ | D17: 最新版のChrome・Safari。スマートフォンの画面幅にも対応する(レスポンシブ) | E17: 案
A18: NF-014 | B18: 環境 | C18: 実行環境 | D18: PHP 8.3以上(Laravel 13の要件)、MySQL。ローカルはMAMP | E18: 確定 | F18: ローカルはPHP 8.4.1を使用
A19: NF-015 | B19: セキュリティ | C19: 出品者・購入者の権限管理 | D19: 出品者は自分の商品だけ編集・削除できる。連絡掲示板は、その商品の出品者と問い合わせた購入者だけが見られる。Laravelの認可の仕組み(Policy)で、本人かを確認する | E19: 案 | F19: 出品者が複数いる前提(Q-001)のため必要
A20: NF-016 | B20: セキュリティ | C20: XSS対策 | D20: 利用者が入力した文章(掲示板・商品説明など)は、Bladeの {{ }} で出力する(自動でエスケープされる)。{!! !!} は使わない | E20: 確定 | F20: 連絡掲示板で利用者の入力を表示するため

Sheet 画面一覧
A1: 画面一覧
A2: 黄色のセルが編集用です。「関連機能名」「フェーズ」は、関連機能IDから機能要件一覧を参照して自動表示されます。URLは案です。マイページ(Lesson 25)の画面は、内容が決まってから追加します(Q-012)。
A4: 画面ID | B4: 画面名 | C4: URL(案) | D4: 認証 | E4: 概要 | F4: 関連機能ID | G4: 関連機能名 | H4: フェーズ | I4: 状況
A5: S-001 | B5: 商品一覧 | C5: /products | D5: 不要 | E5: 商品を一覧で表示する(トップページ) | F5: F-010 | G5: =IFERROR(INDEX(機能要件一覧!$C$5:$C$28,MATCH(F5,機能要件一覧!$A$5:$A$28,0)),"") -> 商品一覧表示 | H5: =IFERROR(INDEX(機能要件一覧!$G$5:$G$28,MATCH(F5,機能要件一覧!$A$5:$A$28,0)),"") -> Phase1 | I5: 未着手
A6: S-002 | B6: 商品詳細 | C6: /products/{id} | D6: 不要 | E6: 商品の説明と、カートに入れるボタン | F6: F-011 | G6: =IFERROR(INDEX(機能要件一覧!$C$5:$C$28,MATCH(F6,機能要件一覧!$A$5:$A$28,0)),"") -> 商品詳細表示 | H6: =IFERROR(INDEX(機能要件一覧!$G$5:$G$28,MATCH(F6,機能要件一覧!$A$5:$A$28,0)),"") -> Phase1 | I6: 未着手
A7: S-003 | B7: カート | C7: /cart | D7: 要ログイン | E7: 入れた商品の確認・数量変更・削除 | F7: F-014 | G7: =IFERROR(INDEX(機能要件一覧!$C$5:$C$28,MATCH(F7,機能要件一覧!$A$5:$A$28,0)),"") -> カート | H7: =IFERROR(INDEX(機能要件一覧!$G$5:$G$28,MATCH(F7,機能要件一覧!$A$5:$A$28,0)),"") -> Phase1 | I7: 未着手
A8: S-004 | B8: 注文確認 | C8: /orders/confirm | D8: 要ログイン | E8: 注文内容を確認して確定する | F8: F-015 | G8: =IFERROR(INDEX(機能要件一覧!$C$5:$C$28,MATCH(F8,機能要件一覧!$A$5:$A$28,0)),"") -> 注文確定(決済なし) | H8: =IFERROR(INDEX(機能要件一覧!$G$5:$G$28,MATCH(F8,機能要件一覧!$A$5:$A$28,0)),"") -> Phase1 | I8: 未着手
A9: S-005 | B9: 注文完了 | C9: /orders/complete | D9: 要ログイン | E9: 注文が完了したことを表示する | F9: F-015 | G9: =IFERROR(INDEX(機能要件一覧!$C$5:$C$28,MATCH(F9,機能要件一覧!$A$5:$A$28,0)),"") -> 注文確定(決済なし) | H9: =IFERROR(INDEX(機能要件一覧!$G$5:$G$28,MATCH(F9,機能要件一覧!$A$5:$A$28,0)),"") -> Phase1 | I9: 未着手
A10: S-006 | B10: 会員登録 | C10: /register | D10: 不要 | E10: 新規会員登録フォーム | F10: F-001 | G10: =IFERROR(INDEX(機能要件一覧!$C$5:$C$28,MATCH(F10,機能要件一覧!$A$5:$A$28,0)),"") -> ユーザー登録 | H10: =IFERROR(INDEX(機能要件一覧!$G$5:$G$28,MATCH(F10,機能要件一覧!$A$5:$A$28,0)),"") -> Phase1 | I10: 未着手
A11: S-007 | B11: ログイン | C11: /login | D11: 不要 | E11: ログインフォーム | F11: F-002 | G11: =IFERROR(INDEX(機能要件一覧!$C$5:$C$28,MATCH(F11,機能要件一覧!$A$5:$A$28,0)),"") -> ログイン | H11: =IFERROR(INDEX(機能要件一覧!$G$5:$G$28,MATCH(F11,機能要件一覧!$A$5:$A$28,0)),"") -> Phase1 | I11: 未着手
A12: S-008 | B12: プロフィール編集 | C12: /profile | D12: 要ログイン | E12: プロフィールの登録・変更 | F12: F-005 | G12: =IFERROR(INDEX(機能要件一覧!$C$5:$C$28,MATCH(F12,機能要件一覧!$A$5:$A$28,0)),"") -> プロフィール編集 | H12: =IFERROR(INDEX(機能要件一覧!$G$5:$G$28,MATCH(F12,機能要件一覧!$A$5:$A$28,0)),"") -> Phase1 | I12: 未着手
A13: S-009 | B13: パスワード変更 | C13: /password | D13: 要ログイン | E13: ログイン中のパスワード変更 | F13: F-006 | G13: =IFERROR(INDEX(機能要件一覧!$C$5:$C$28,MATCH(F13,機能要件一覧!$A$5:$A$28,0)),"") -> パスワード変更 | H13: =IFERROR(INDEX(機能要件一覧!$G$5:$G$28,MATCH(F13,機能要件一覧!$A$5:$A$28,0)),"") -> Phase1 | I13: 未着手
A14: S-010 | B14: パスワード再設定 | C14: /password/reset | D14: 不要 | E14: パスワードを忘れたときの再設定 | F14: F-007 | G14: =IFERROR(INDEX(機能要件一覧!$C$5:$C$28,MATCH(F14,機能要件一覧!$A$5:$A$28,0)),"") -> パスワードリマインダー | H14: =IFERROR(INDEX(機能要件一覧!$G$5:$G$28,MATCH(F14,機能要件一覧!$A$5:$A$28,0)),"") -> Phase1 | I14: 未着手
A15: S-011 | B15: 注文履歴 | C15: /orders | D15: 要ログイン | E15: 過去の注文の一覧・詳細 | F15: F-016 | G15: =IFERROR(INDEX(機能要件一覧!$C$5:$C$28,MATCH(F15,機能要件一覧!$A$5:$A$28,0)),"") -> 注文履歴表示 | H15: =IFERROR(INDEX(機能要件一覧!$G$5:$G$28,MATCH(F15,機能要件一覧!$A$5:$A$28,0)),"") -> Phase2 | I15: 未着手
A16: S-012 | B16: お気に入り一覧 | C16: /favorites | D16: 要ログイン | E16: お気に入りに登録した商品の一覧 | F16: F-013 | G16: =IFERROR(INDEX(機能要件一覧!$C$5:$C$28,MATCH(F16,機能要件一覧!$A$5:$A$28,0)),"") -> お気に入り登録 | H16: =IFERROR(INDEX(機能要件一覧!$G$5:$G$28,MATCH(F16,機能要件一覧!$A$5:$A$28,0)),"") -> Phase1 | I16: 未着手
... A24: S-020 | B24: 出品者:問い合わせ返信 | C24: /seller/messages/{product_id}/{buyer_id} | D24: 出品者 | E24: 問い合わせを開いて返信する(案) | F24: F-024 | G24: =IFERROR(INDEX(機能要件一覧!$C$5:$C$28,MATCH(F24,機能要件一覧!$A$5:$A$28,0)),"") -> 連絡掲示板 | H24: =IFERROR(INDEX(機能要件一覧!$G$5:$G$28,MATCH(F24,機能要件一覧!$A$5:$A$28,0)),"") -> Phase1 | I24: 未着手

Sheet テーブル定義
A1: テーブル定義
A2: Lesson 06 のマイグレーション(2026/10/26 作成)に合わせて更新しました。「マイグレーション」が未作成のテーブル(カート・注文)は案です。マイグレーションを変えたら、ここも更新してください。
A4: テーブル名 | B4: カラム名 | C4: 型 | D4: NULL | E4: キー・制約 | F4: 説明 | G4: フェーズ | H4: マイグレーション
A5: users | B5: id | C5: bigint unsigned | D5: NOT NULL | E5: PK / AUTO_INCREMENT | F5: 会員ID | G5: Phase1 | H5: 作成済み
A6: users | B6: name | C6: varchar(255) | D6: NULL | F6: 名前(Laravel標準のUserモデルに合わせた列名) | G6: Phase1 | H6: 作成済み
A7: users | B7: age | C7: int | D7: NULL | F7: 年齢 | G7: Phase1 | H7: 作成済み
A8: users | B8: tel | C8: varchar(255) | D8: NULL | F8: 電話番号 | G8: Phase1 | H8: 作成済み
A9: users | B9: zip | C9: varchar(255) | D9: NULL | F9: 郵便番号(先頭の0を残すため文字列) | G9: Phase1 | H9: 作成済み
A10: users | B10: addr | C10: varchar(255) | D10: NULL | F10: 住所 | G10: Phase1 | H10: 作成済み
A11: users | B11: email | C11: varchar(255) | D11: NOT NULL | E11: UNIQUE | F11: メールアドレス(ログインID) | G11: Phase1 | H11: 作成済み
A12: users | B12: password | C12: varchar(255) | D12: NOT NULL | F12: パスワード(ハッシュ化して保存) | G12: Phase1 | H12: 作成済み
A13: users | B13: login_time | C13: datetime | D13: NULL | F13: 最終ログイン日時 | G13: Phase1 | H13: 作成済み
A14: users | B14: pic | C14: varchar(255) | D14: NULL | F14: プロフィール画像のパス | G14: Phase1 | H14: 作成済み
A15: users | B15: created_at, updated_at | C15: timestamp | D15: NULL | F15: 作成・更新日時(timestamps()。Laravelが自動で入れる) | G15: Phase1 | H15: 作成済み
A16: users | B16: deleted_at | C16: timestamp | D16: NULL | F16: 論理削除(softDeletes())。空なら有効、日時が入っていれば削除済み | G16: Phase1 | H16: 作成済み
A17: sessions | B17: (Laravel標準) | C17: - | D17: - | F17: ログイン状態などの保存先。.env の SESSION_DRIVER=database のため必須 | G17: Phase1 | H17: 作成済み
A18: cache / jobs | B18: (Laravel標準) | C18: - | D18: - | F18: Laravelが最初から用意しているテーブル | G18: Phase1 | H18: 作成済み
A19: categories | B19: id | C19: bigint unsigned | D19: NOT NULL | E19: PK / AUTO_INCREMENT | F19: カテゴリID | G19: Phase1 | H19: 作成済み
A20: categories | B20: name | C20: varchar(255) | D20: NOT NULL | F20: カテゴリ名 | G20: Phase1 | H20: 作成済み
A21: categories | B21: created_at, updated_at | C21: timestamp | D21: NULL | F21: 作成・更新日時(timestamps()。Laravelが自動で入れる) | G21: Phase1 | H21: 作成済み
A22: categories | B22: deleted_at | C22: timestamp | D22: NULL | F22: 論理削除(softDeletes())。空なら有効、日時が入っていれば削除済み | G22: Phase1 | H22: 作成済み
A23: products | B23: id | C23: bigint unsigned | D23: NOT NULL | E23: PK / AUTO_INCREMENT | F23: 商品ID | G23: Phase1 | H23: 作成済み
A24: products | B24: name | C24: varchar(255) | D24: NOT NULL | F24: 商品名 | G24: Phase1 | H24: 作成済み
A25: products | B25: category_id | C25: bigint unsigned | D25: NOT NULL | E25: FK → categories.id | F25: カテゴリ | G25: Phase1 | H25: 作成済み
A26: products | B26: comment | C26: varchar(255) | D26: NOT NULL | F26: 商品説明(255文字まで) | G26: Phase1 | H26: 作成済み
A27: products | B27: price | C27: int | D27: NOT NULL | F27: 価格(円) | G27: Phase1 | H27: 作成済み
A28: products | B28: pic1 | C28: varchar(255) | D28: NOT NULL | F28: 商品画像1のパス(必須) | G28: Phase1 | H28: 作成済み
A29: products | B29: pic2 | C29: varchar(255) | D29: NULL | F29: 商品画像2のパス | G29: Phase1 | H29: 作成済み
A30: products | B30: pic3 | C30: varchar(255) | D30: NULL | F30: 商品画像3のパス | G30: Phase1 | H30: 作成済み
A31: products | B31: sell_user_id | C31: bigint unsigned | D31: NOT NULL | E31: FK → users.id | F31: 出品者(商品を登録した会員) | G31: Phase1 | H31: 作成済み
A32: products | B32: deleted_at | C32: timestamp | D32: NULL | F32: 論理削除(softDeletes())。空なら有効、日時が入っていれば削除済み | G32: Phase1 | H32: 作成済み
A33: products | B33: created_at, updated_at | C33: timestamp | D33: NULL | F33: 作成・更新日時(timestamps()。Laravelが自動で入れる) | G33: Phase1 | H33: 作成済み
A34: message_boards | B34: id | C34: bigint unsigned | D34: NOT NULL | E34: PK / AUTO_INCREMENT | F34: 掲示板ID(販売者と購入者のやり取りの部屋) | G34: Phase1 | H34: 作成済み
A35: message_boards | B35: sale_user_id | C35: bigint unsigned | D35: NOT NULL | E35: FK → users.id | F35: 販売者 | G35: Phase1 | H35: 作成済み
A36: message_boards | B36: buy_user_id | C36: bigint unsigned | D36: NOT NULL | E36: FK → users.id | F36: 購入者 | G36: Phase1 | H36: 作成済み
A37: message_boards | B37: product_id | C37: bigint unsigned | D37: NOT NULL | E37: FK → products.id | F37: やり取りの対象の商品 | G37: Phase1 | H37: 作成済み
A38: message_boards | B38: deleted_at | C38: timestamp | D38: NULL | F38: 論理削除(softDeletes())。空なら有効、日時が入っていれば削除済み | G38: Phase1 | H38: 作成済み
A39: message_boards | B39: created_at, updated_at | C39: timestamp | D39: NULL | F39: 作成・更新日時(timestamps()。Laravelが自動で入れる) | G39: Phase1 | H39: 作成済み
A40: messages | B40: id | C40: bigint unsigned | D40: NOT NULL | E40: PK / AUTO_INCREMENT | F40: メッセージID | G40: Phase1 | H40: 作成済み
A41: messages | B41: board_id | C41: bigint unsigned | D41: NOT NULL | E41: FK → message_boards.id | F41: 所属する掲示板 | G41: Phase1 | H41: 作成済み
...

Sheet 課題・確認事項
A1: 課題・確認事項
A2: 黄色のセルが編集用です。決めたら「状況」を「決定」にして、決定日を入れてください。
A4: ID | B4: 区分 | C4: 内容 | D4: 選択肢 | E4: 現時点の方針 | F4: 関連機能ID | G4: 状況 | H4: 決定日
A5: Q-001 | B5: 仕様 | C5: 商品を登録するのは誰か | D5: A:管理者のみ(単独ショップ) / B:出品者が複数(販売側ユーザー登録が必要) | E5: B(出品者が複数)に決定。出品者による商品の登録・編集・削除(F-018〜F-020)を作る。商品は出品者に紐づける(products.sell_user_id)。会員はroleで分けず、どの会員でも出品・購入できる(2026/10/26)。そのため出品者専用の登録(F-009)は作らない | F5: F-009, F-018〜F-020 | G5: 決定 | H5: 46311
A6: Q-002 | B6: 仕様 | C6: 決済をどう扱うか | D6: A:決済なしで注文確定 / B:外部決済サービスを連携 | E6: A(決済なし)でPhase1を作る | F6: F-015, F-017 | G6: 仮決定
A7: Q-003 | B7: 仕様 | C7: 配送先住所をどう持たせるか | D7: A:プロフィールの住所を使う / B:注文時に入力して注文に保存する | E7: プロフィール機能(Lesson 12〜14の想定)の内容を見てから決める。決まるまでは配送先を扱わない | F7: F-004, F-015 | G7: 未決
A8: Q-004 | B8: 仕様 | C8: 在庫・売り切れをどう扱うか | D8: A:1点もの(フリマ型。買われたら売り切れ) / B:在庫数を持ち、注文時に減らす | E8: A(1点もの)に決定。在庫数の列は持たず、カート・注文の数量は常に1。売り切れの判定方法(注文明細の有無で判定する / productsに売れた日時の列を足す)は、注文確定(F-015)を作るときに決める | F8: F-015, F-021 | G8: 決定 | H8: 46321
A9: Q-005 | B9: 技術 | C9: 認証の実装方法 | D9: A:Laravelのスターターキット等を使う / B:教材のように自作する | E9: 案:B。教材のレッスン(Lesson 09〜11)に沿って自作する。スターターキットを使うと、教材の流れと合わなくなる | F9: F-001〜F-003 | G9: 未決
A10: Q-006 | B10: 技術 | C10: 商品画像の保存先 | D10: A:サーバー内(storage) / B:S3 | E10: 案:Lesson 17〜19(商品登録)で必要になる。まずサーバー内(storage)で作り、S3への切り替えはAWS公開時に検討する | F10: F-010, F-018 | G10: 未決
A11: Q-007 | B11: 技術 | C11: 本番の構成 | D11: A:EC2 + RDS / B:EC2内にMySQL | E11: インフラ部の構成に合わせる | F11: - | G11: 未決
A12: Q-008 | B12: 運用 | C12: パスワード再設定メールの送信方法 | D12: 開発中:Laravelのログ出力(メールを実際には送らず、ログに書き出す) / 本番:メール送信サービスを使う(AWS SESなど) | E12: Lesson 16(パスワードリマインダー)を作るため、Phase1で必要になる。メール通知(F-022)は対象外のままだが、再設定メールの送信だけは別に必要 | F12: F-007, F-022 | G12: 未決
A13: Q-009 | B13: 技術 | C13: Phase1の商品データの用意方法 | D13: A:シーダー(初期データ投入) / B:商品登録機能で登録する | E13: B。教材順では商品登録(Lesson 17〜19)を先に作るため、シーダーは必須でなくなった。画面確認用のダミーデータが欲しいときだけ使う | F13: F-010 | G13: 仮決定
A14: Q-010 | B14: 仕様 | C14: 1回の注文に、複数の出品者の商品を含めてよいか | D14: A:含めてよい(注文は購入者単位。明細から出品者が分かる) / B:出品者ごとに注文を分ける | E14: A(含めてよい)で進める | F14: F-015 | G14: 仮決定
A15: Q-011 | B15: 仕様 | C15: 連絡掲示板(Lesson 23)を入れるか | D15: 入れる / 入れない | E15: 入れる(決定)。形は「商品ごとの、購入者と出品者の1対1」とする(案)。Lesson 23の内容に合わせて見直す | F15: F-024 | G15: 決定 | H15: 46312
A16: Q-012 | B16: 仕様 | C16: マイページ(Lesson 25)に何を入れるか | D16: 例:プロフィール、出品した商品、注文履歴、お気に入り、問い合わせ | E16: Lesson 25の動画を見てから決める。注文履歴(F-016)を入れる場合はPhase1に移す | F16: (未定) | G16: 未決

Sheet スケジュール
A1: スケジュール(教材のレッスン順)
A2: 黄色のセル(レッスン数・実装工数・状況)を変えると、予定開始・予定終了が自動で更新されます。日程は、毎日の再現練習の時間を差し引いた「開発に使う時間」で計算しています。合計見積 =(レッスン数 × 1レッスンの時間 + 実装工数)×(1 + 予備率)。時間の設定は「稼働カレンダー」シートで変更できます。
A4: No | B4: フェーズ | C4: 教材レッスン | D4: タスク | E4: 対応機能ID | F4: 想定ブランチ | G4: 成果物 | H4: レッスン数 | I4: 実装工数(h) | J4: 合計見積(h) | K4: 累積(h) | L4: 予定開始 | M4: 予定終了 | N4: 状況
A5: 1 | B5: 準備 | C5: - | D5: ローカル環境構築(Laravel作成・GitHub連携) | E5: - | F5: main | G5: 動作するLaravelプロジェクト、GitHubリポジトリ | H5: 0 | I5: 4 | J5: =IF(N5="完了",0,(H5*稼働カレンダー!$B$8+I5)*(1+稼働カレンダー!$B$7)) -> 0 | K5: =ROUND(SUM($J$5:J5),6) -> 0 | L5: =IF(N5="完了","完了",IFERROR(INDEX(稼働カレンダー!$A$16:$A$215,COUNTIF(稼働カレンダー!$G$16:$G$215,"<="&ROUND(K5-J5,6))+1),"範囲外")) -> 完了 | M5: =IF(N5="完了","完了",IFERROR(INDEX(稼働カレンダー!$A$16:$A$215,COUNTIF(稼働カレンダー!$G$16:$G$215,"<"&K5)+1),"範囲外")) -> 完了 | N5: 完了
A6: 2 | B6: 要件定義 | C6: Lesson 01 | D6: 要件定義書の作成・確定(機能の洗い出し) | E6: - | F6: - | G6: 本ファイル | H6: 0 | I6: 3 | J6: =IF(N6="完了",0,(H6*稼働カレンダー!$B$8+I6)*(1+稼働カレンダー!$B$7)) -> 0 | K6: =ROUND(SUM($J$5:J6),6) -> 0 | L6: =IF(N6="完了","完了",IFERROR(INDEX(稼働カレンダー!$A$16:$A$215,COUNTIF(稼働カレンダー!$G$16:$G$215,"<="&ROUND(K6-J6,6))+1),"範囲外")) -> 完了 | M6: =IF(N6="完了","完了",IFERROR(INDEX(稼働カレンダー!$A$16:$A$215,COUNTIF(稼働カレンダー!$G$16:$G$215,"<"&K6)+1),"範囲外")) -> 完了 | N6: 完了
A7: 3 | B7: 設計 | C7: Lesson 02 | D7: 画面設計(画面一覧の確定)。動画は視聴済み。マイページ追加などの反映が残り | E7: - | F7: - | G7: 画面一覧 | H7: 0 | I7: 1 | J7: =IF(N7="完了",0,(H7*稼働カレンダー!$B$8+I7)*(1+稼働カレンダー!$B$7)) -> 0 | K7: =ROUND(SUM($J$5:J7),6) -> 0 | L7: =IF(N7="完了","完了",IFERROR(INDEX(稼働カレンダー!$A$16:$A$215,COUNTIF(稼働カレンダー!$G$16:$G$215,"<="&ROUND(K7-J7,6))+1),"範囲外")) -> 完了 | M7: =IF(N7="完了","完了",IFERROR(INDEX(稼働カレンダー!$A$16:$A$215,COUNTIF(稼働カレンダー!$G$16:$G$215,"<"&K7)+1),"範囲外")) -> 完了 | N7: 完了
A8: 4 | B8: 設計 | C8: Lesson 03〜05 | D8: テーブル設計(テーブル定義の確定)。動画は視聴済み。型・削除フラグ・categories・message_boardsの反映が残り | E8: - | F8: - | G8: テーブル定義 | H8: 0 | I8: 2 | J8: =IF(N8="完了",0,(H8*稼働カレンダー!$B$8+I8)*(1+稼働カレンダー!$B$7)) -> 0 | K8: =ROUND(SUM($J$5:J8),6) -> 0 | L8: =IF(N8="完了","完了",IFERROR(INDEX(稼働カレンダー!$A$16:$A$215,COUNTIF(稼働カレンダー!$G$16:$G$215,"<="&ROUND(K8-J8,6))+1),"範囲外")) -> 完了 | M8: =IF(N8="完了","完了",IFERROR(INDEX(稼働カレンダー!$A$16:$A$215,COUNTIF(稼働カレンダー!$G$16:$G$215,"<"&K8)+1),"範囲外")) -> 完了 | N8: 完了
A9: 5 | B9: 設計 | C9: Lesson 06 | D9: DB作成(MySQL・.env設定・マイグレーション) | E9: - | F9: feature/database | G9: 動作するDB、マイグレーションファイル | H9: 1 | I9: 2 | J9: =IF(N9="完了",0,(H9*稼働カレンダー!$B$8+I9)*(1+稼働カレンダー!$B$7)) -> 0 | K9: =ROUND(SUM($J$5:J9),6) -> 0 | L9: =IF(N9="完了","完了",IFERROR(INDEX(稼働カレンダー!$A$16:$A$215,COUNTIF(稼働カレンダー!$G$16:$G$215,"<="&ROUND(K9-J9,6))+1),"範囲外")) -> 完了 | M9: =IF(N9="完了","完了",IFERROR(INDEX(稼働カレンダー!$A$16:$A$215,COUNTIF(稼働カレンダー!$G$16:$G$215,"<"&K9)+1),"範囲外")) -> 完了 | N9: 完了
A10: 6 | B10: 実装(Phase1) | C10: Lesson 07〜08 | D10: 画面の見た目を作る(共通レイアウト、主要画面) | E10: - | F10: feature/layout | G10: 共通レイアウト、主要画面のHTML/CSS | H10: 2 | I10: 6 | J10: =IF(N10="完了",0,(H10*稼働カレンダー!$B$8+I10)*(1+稼働カレンダー!$B$7)) -> 8.4 | K10: =ROUND(SUM($J$5:J10),6) -> 8.4 | L10: =IF(N10="完了","完了",IFERROR(INDEX(稼働カレンダー!$A$16:$A$215,COUNTIF(稼働カレンダー!$G$16:$G$215,"<="&ROUND(K10-J10,6))+1),"範囲外")) -> 46317 | M10: =IF(N10="完了","完了",IFERROR(INDEX(稼働カレンダー!$A$16:$A$215,COUNTIF(稼働カレンダー!$G$16:$G$215,"<"&K10)+1),"範囲外")) -> 46319 | N10: 未着手
A11: 7 | B11: 実装(Phase1) | C11: Lesson 09〜11 | D11: 会員登録・ログイン | E11: F-001, F-002 | F11: feature/auth | G11: 会員登録・ログイン機能 | H11: 3 | I11: 3 | J11: =IF(N11="完了",0,(H11*稼働カレンダー!$B$8+I11)*(1+稼働カレンダー!$B$7)) -> 5.4 | K11: =ROUND(SUM($J$5:J11),6) -> 13.8 | L11: =IF(N11="完了","完了",IFERROR(INDEX(稼働カレンダー!$A$16:$A$215,COUNTIF(稼働カレンダー!$G$16:$G$215,"<="&ROUND(K11-J11,6))+1),"範囲外")) -> 46319 | M11: =IF(N11="完了","完了",IFERROR(INDEX(稼働カレンダー!$A$16:$A$215,COUNTIF(稼働カレンダー!$G$16:$G$215,"<"&K11)+1),"範囲外")) -> 46319 | N11: 未着手
A12: 8 | B12: 実装(Phase1) | C12: Lesson 12〜14(要確認) | D12: ログアウト・プロフィール・退会・出品者登録など(内容は要確認) | E12: F-003〜F-005, F-008, F-009 | F12: feature/profile 他 | G12: 該当機能 | H12: 3 | I12: 4 | J12: =IF(N12="完了",0,(H12*稼働カレンダー!$B$8+I12)*(1+稼働カレンダー!$B$7)) -> 6.6 | K12: =ROUND(SUM($J$5:J12),6) -> 20.4 | L12: =IF(N12="完了","完了",IFERROR(INDEX(稼働カレンダー!$A$16:$A$215,COUNTIF(稼働カレンダー!$G$16:$G$215,"<="&ROUND(K12-J12,6))+1),"範囲外")) -> 46319 | M12: =IF(N12="完了","完了",IFERROR(INDEX(稼働カレンダー!$A$16:$A$215,COUNTIF(稼働カレンダー!$G$16:$G$215,"<"&K12)+1),"範囲外")) -> 46320 | N12: 未着手
A13: 9 | B13: 実装(Phase1) | C13: Lesson 15〜16 | D13: パスワード変更・パスワードリマインダー | E13: F-006, F-007 | F13: feature/password | G13: パスワード関連の機能 | H13: 2 | I13: 3 | J13: =IF(N13="完了",0,(H13*稼働カレンダー!$B$8+I13)*(1+稼働カレンダー!$B$7)) -> 4.8 | K13: =ROUND(SUM($J$5:J13),6) -> 25.2 | L13: =IF(N13="完了","完了",IFERROR(INDEX(稼働カレンダー!$A$16:$A$215,COUNTIF(稼働カレンダー!$G$16:$G$215,"<="&ROUND(K13-J13,6))+1),"範囲外")) -> 46320 | M13: =IF(N13="完了","完了",IFERROR(INDEX(稼働カレンダー!$A$16:$A$215,COUNTIF(稼働カレンダー!$G$16:$G$215,"<"&K13)+1),"範囲外")) -> 46321 | N13: 未着手
A14: 10 | B14: 実装(Phase1) | C14: Lesson 17〜19 | D14: 出品者による商品登録(編集・削除を含む。教材の範囲は要確認) | E14: F-018〜F-020 | F14: feature/product-register | G14: 商品登録・編集・削除 | H14: 3 | I14: 4 | J14: =IF(N14="完了",0,(H14*稼働カレンダー!$B$8+I14)*(1+稼働カレンダー!$B$7)) -> 6.6 | K14: =ROUND(SUM($J$5:J14),6) -> 31.8 | L14: =IF(N14="完了","完了",IFERROR(INDEX(稼働カレンダー!$A$16:$A$215,COUNTIF(稼働カレンダー!$G$16:$G$215,"<="&ROUND(K14-J14,6))+1),"範囲外")) -> 46321 | M14: =IF(N14="完了","完了",IFERROR(INDEX(稼働カレンダー!$A$16:$A$215,COUNTIF(稼働カレンダー!$G$16:$G$215,"<"&K14)+1),"範囲外")) -> 46323 | N14: 未着手
A15: 11 | B15: 実装(Phase1) | C15: Lesson 20〜21 | D15: 商品一覧・商品詳細 | E15: F-010, F-011 | F15: feature/product-list | G15: 商品一覧・詳細画面 | H15: 2 | I15: 2 | J15: =IF(N15="完了",0,(H15*稼働カレンダー!$B$8+I15)*(1+稼働カレンダー!$B$7)) -> 3.6 | K15: =ROUND(SUM($J$5:J15),6) -> 35.4 | L15: =IF(N15="完了","完了",IFERROR(INDEX(稼働カレンダー!$A$16:$A$215,COUNTIF(稼働カレンダー!$G$16:$G$215,"<="&ROUND(K15-J15,6))+1),"範囲外")) -> 46323 | M15: =IF(N15="完了","完了",IFERROR(INDEX(稼働カレンダー!$A$16:$A$215,COUNTIF(稼働カレンダー!$G$16:$G$215,"<"&K15)+1),"範囲外")) -> 46324 | N15: 未着手
A16: 12 | B16: 実装(Phase1) | C16: Lesson 22 | D16: 商品検索 | E16: F-012 | F16: feature/search | G16: 検索機能 | H16: 1 | I16: 1 | J16: =IF(N16="完了",0,(H16*稼働カレンダー!$B$8+I16)*(1+稼働カレンダー!$B$7)) -> 1.8 | K16: =ROUND(SUM($J$5:J16),6) -> 37.2 | L16: =IF(N16="完了","完了",IFERROR(INDEX(稼働カレンダー!$A$16:$A$215,COUNTIF(稼働カレンダー!$G$16:$G$215,"<="&ROUND(K16-J16,6))+1),"範囲外")) -> 46324 | M16: =IF(N16="完了","完了",IFERROR(INDEX(稼働カレンダー!$A$16:$A$215,COUNTIF(稼働カレンダー!$G$16:$G$215,"<"&K16)+1),"範囲外")) -> 46325 | N16: 未着手
... A25: 21 | B25: Phase2 | C25: (教材外) | D25: 注文履歴 | E25: F-016 | F25: feature/order-history | G25: 注文履歴画面 | H25: 0 | I25: 5 | J25: =IF(N25="完了",0,(H25*稼働カレンダー!$B$8+I25)*(1+稼働カレンダー!$B$7)) -> 6 | K25: =ROUND(SUM($J$5:J25),6) -> 108.6 | L25: =IF(N25="完了","完了",IFERROR(INDEX(稼働カレンダー!$A$16:$A$215,COUNTIF(稼働カレンダー!$G$16:$G$215,"<="&ROUND(K25-J25,6))+1),"範囲外")) -> 46337 | M25: =IF(N25="完了","完了",IFERROR(INDEX(稼働カレンダー!$A$16:$A$215,COUNTIF(稼働カレンダー!$G$16:$G$215,"<"&K25)+1),"範囲外")) -> 46339 | N25: 未着手
G26: 合計 | H26: =SUM(H5:H25) -> 20 | I26: =SUM(I5:I25) -> 93 | J26: =SUM(J5:J25) -> 108.6

Sheet 稼働カレンダー
A1: 稼働カレンダー
A2: スケジュールの日程は、このシートの稼働時間から自動計算されます。黄色のセルが編集用です。
A4: 起算日 | B4: 46317
A5: 平日の稼働時間(h) | B5: 4.5
A6: 休日の稼働時間(h) | B6: 10
A7: 予備率(見積への上乗せ) | B7: 0.2
A8: 1レッスンあたりの視聴・演習時間(h) | B8: 0.5
A9: うち平日の再現練習(h) | B9: 1
A10: うち休日の再現・白紙練習(h) | B10: 2
A11: 開発に使う時間 = 稼働時間 − 再現練習の時間。教材を見ずに作り直す練習(フルスクラッチ練習)の時間を、先に確保してから日程を計算します。
A12: 休日は土日祝として計算します。特定の日だけ変えたいときは、表の「上書き」で平日/休日を選んでください。
A13: 祝日は右の表に入力済み(2027/2/23まで)。足りない日は表に追記してください。
A14: 「1レッスンあたりの視聴・演習時間」は仮の値です。レッスンページの「学習にかかった時間」の実績に合わせて変えてください。
A15: 日付 | B15: 曜日 | C15: 自動判定 | D15: 上書き | E15: 区分 | F15: 開発に使う時間(h) | G15: 累積(h) | I15: 祝日 | J15: 名称
A16: =$B$4 -> 46317 | B16: =CHOOSE(WEEKDAY(A16),"日","月","火","水","木","金","土") -> 木 | C16: =IF(OR(WEEKDAY(A16,2)>5,COUNTIF($I$16:$I$35,A16)>0),"休日","平日") -> 平日 | E16: =IF(D16<>"",D16,C16) -> 平日 | F16: =IF(E16="休日",MAX(0,$B$6-$B$10),MAX(0,$B$5-$B$9)) -> 3.5 | G16: =F16 -> 3.5 | I16: 46329 | J16: 文化の日
A17: =A16+1 -> 46318 | B17: =CHOOSE(WEEKDAY(A17),"日","月","火","水","木","金","土") -> 金 | C17: =IF(OR(WEEKDAY(A17,2)>5,COUNTIF($I$16:$I$35,A17)>0),"休日","平日") -> 平日 | E17: =IF(D17<>"",D17,C17) -> 平日 | F17: =IF(E17="休日",MAX(0,$B$6-$B$10),MAX(0,$B$5-$B$9)) -> 3.5 | G17: =G16+F17 -> 7 | I17: 46349 | J17: 勤労感謝の日
A18: =A17+1 -> 46319 | B18: =CHOOSE(WEEKDAY(A18),"日","月","火","水","木","金","土") -> 土 | C18: =IF(OR(WEEKDAY(A18,2)>5,COUNTIF($I$16:$I$35,A18)>0),"休日","平日") -> 休日 | E18: =IF(D18<>"",D18,C18) -> 休日 | F18: =IF(E18="休日",MAX(0,$B$6-$B$10),MAX(0,$B$5-$B$9)) -> 8 | G18: =G17+F18 -> 15 | I18: 46388 | J18: 元日
A19: =A18+1 -> 46320 | B19: =CHOOSE(WEEKDAY(A19),"日","月","火","水","木","金","土") -> 日 | C19: =IF(OR(WEEKDAY(A19,2)>5,COUNTIF($I$16:$I$35,A19)>0),"休日","平日") -> 休日 | E19: =IF(D19<>"",D19,C19) -> 休日 | F19: =IF(E19="休日",MAX(0,$B$6-$B$10),MAX(0,$B$5-$B$9)) -> 8 | G19: =G18+F19 -> 23 | I19: 46398 | J19: 成人の日
A20: =A19+1 -> 46321 | B20: =CHOOSE(WEEKDAY(A20),"日","月","火","水","木","金","土") -> 月 | C20: =IF(OR(WEEKDAY(A20,2)>5,COUNTIF($I$16:$I$35,A20)>0),"休日","平日") -> 平日 | E20: =IF(D20<>"",D20,C20) -> 平日 | F20: =IF(E20="休日",MAX(0,$B$6-$B$10),MAX(0,$B$5-$B$9)) -> 3.5 | G20: =G19+F20 -> 26.5 | I20: 46429 | J20: 建国記念の日
A21: =A20+1 -> 46322 | B21: =CHOOSE(WEEKDAY(A21),"日","月","火","水","木","金","土") -> 火 | C21: =IF(OR(WEEKDAY(A21,2)>5,COUNTIF($I$16:$I$35,A21)>0),"休日","平日") -> 平日 | E21: =IF(D21<>"",D21,C21) -> 平日 | F21: =IF(E21="休日",MAX(0,$B$6-$B$10),MAX(0,$B$5-$B$9)) -> 3.5 | G21: =G20+F21 -> 30 | I21: 46441 | J21: 天皇誕生日
A22: =A21+1 -> 46323 | B22: =CHOOSE(WEEKDAY(A22),"日","月","火","水","木","金","土") -> 水 | C22: =IF(OR(WEEKDAY(A22,2)>5,COUNTIF($I$16:$I$35,A22)>0),"休日","平日") -> 平日 | E22: =IF(D22<>"",D22,C22) -> 平日 | F22: =IF(E22="休日",MAX(0,$B$6-$B$10),MAX(0,$B$5-$B$9)) -> 3.5 | G22: =G21+F22 -> 33.5
A23: =A22+1 -> 46324 | B23: =CHOOSE(WEEKDAY(A23),"日","月","火","水","木","金","土") -> 木 | C23: =IF(OR(WEEKDAY(A23,2)>5,COUNTIF($I$16:$I$35,A23)>0),"休日","平日") -> 平日 | E23: =IF(D23<>"",D23,C23) -> 平日 | F23: =IF(E23="休日",MAX(0,$B$6-$B$10),MAX(0,$B$5-$B$9)) -> 3.5 | G23: =G22+F23 -> 37
A24: =A23+1 -> 46325 | B24: =CHOOSE(WEEKDAY(A24),"日","月","火","水","木","金","土") -> 金 | C24: =IF(OR(WEEKDAY(A24,2)>5,COUNTIF($I$16:$I$35,A24)>0),"休日","平日") -> 平日 | E24: =IF(D24<>"",D24,C24) -> 平日 | F24: =IF(E24="休日",MAX(0,$B$6-$B$10),MAX(0,$B$5-$B$9)) -> 3.5 | G24: =G23+F24 -> 40.5
A25: =A24+1 -> 46326 | B25: =CHOOSE(WEEKDAY(A25),"日","月","火","水","木","金","土") -> 土 | C25: =IF(OR(WEEKDAY(A25,2)>5,COUNTIF($I$16:$I$35,A25)>0),"休日","平日") -> 休日 | E25: =IF(D25<>"",D25,C25) -> 休日 | F25: =IF(E25="休日",MAX(0,$B$6-$B$10),MAX(0,$B$5-$B$9)) -> 8 | G25: =G24+F25 -> 48.5
A26: =A25+1 -> 46327 | B26: =CHOOSE(WEEKDAY(A26),"日","月","火","水","木","金","土") -> 日 | C26: =IF(OR(WEEKDAY(A26,2)>5,COUNTIF($I$16:$I$35,A26)>0),"休日","平日") -> 休日 | E26: =IF(D26<>"",D26,C26) -> 休日 | F26: =IF(E26="休日",MAX(0,$B$6-$B$10),MAX(0,$B$5-$B$9)) -> 8 | G26: =G25+F26 -> 56.5
A27: =A26+1 -> 46328 | B27: =CHOOSE(WEEKDAY(A27),"日","月","火","水","木","金","土") -> 月 | C27: =IF(OR(WEEKDAY(A27,2)>5,COUNTIF($I$16:$I$35,A27)>0),"休日","平日") -> 平日 | E27: =IF(D27<>"",D27,C27) -> 平日 | F27: =IF(E27="休日",MAX(0,$B$6-$B$10),MAX(0,$B$5-$B$9)) -> 3.5 | G27: =G26+F27 -> 60
A28: =A27+1 -> 46329 | B28: =CHOOSE(WEEKDAY(A28),"日","月","火","水","木","金","土") -> 火 | C28: =IF(OR(WEEKDAY(A28,2)>5,COUNTIF($I$16:$I$35,A28)>0),"休日","平日") -> 休日 | E28: =IF(D28<>"",D28,C28) -> 休日 | F28: =IF(E28="休日",MAX(0,$B$6-$B$10),MAX(0,$B$5-$B$9)) -> 8 | G28: =G27+F28 -> 68
A29: =A28+1 -> 46330 | B29: =CHOOSE(WEEKDAY(A29),"日","月","火","水","木","金","土") -> 水 | C29: =IF(OR(WEEKDAY(A29,2)>5,COUNTIF($I$16:$I$35,A29)>0),"休日","平日") -> 平日 | E29: =IF(D29<>"",D29,C29) -> 平日 | F29: =IF(E29="休日",MAX(0,$B$6-$B$10),MAX(0,$B$5-$B$9)) -> 3.5 | G29: =G28+F29 -> 71.5
A30: =A29+1 -> 46331 | B30: =CHOOSE(WEEKDAY(A30),"日","月","火","水","木","金","土") -> 木 | C30: =IF(OR(WEEKDAY(A30,2)>5,COUNTIF($I$16:$I$35,A30)>0),"休日","平日") -> 平日 | E30: =IF(D30<>"",D30,C30) -> 平日 | F30: =IF(E30="休日",MAX(0,$B$6-$B$10),MAX(0,$B$5-$B$9)) -> 3.5 | G30: =G29+F30 -> 75
A31: =A30+1 -> 46332 | B31: =CHOOSE(WEEKDAY(A31),"日","月","火","水","木","金","土") -> 金 | C31: =IF(OR(WEEKDAY(A31,2)>5,COUNTIF($I$16:$I$35,A31)>0),"休日","平日") -> 平日 | E31: =IF(D31<>"",D31,C31) -> 平日 | F31: =IF(E31="休日",MAX(0,$B$6-$B$10),MAX(0,$B$5-$B$9)) -> 3.5 | G31: =G30+F31 -> 78.5
A32: =A31+1 -> 46333 | B32: =CHOOSE(WEEKDAY(A32),"日","月","火","水","木","金","土") -> 土 | C32: =IF(OR(WEEKDAY(A32,2)>5,COUNTIF($I$16:$I$35,A32)>0),"休日","平日") -> 休日 | E32: =IF(D32<>"",D32,C32) -> 休日 | F32: =IF(E32="休日",MAX(0,$B$6-$B$10),MAX(0,$B$5-$B$9)) -> 8 | G32: =G31+F32 -> 86.5
A33: =A32+1 -> 46334 | B33: =CHOOSE(WEEKDAY(A33),"日","月","火","水","木","金","土") -> 日 | C33: =IF(OR(WEEKDAY(A33,2)>5,COUNTIF($I$16:$I$35,A33)>0),"休日","平日") -> 休日 | E33: =IF(D33<>"",D33,C33) -> 休日 | F33: =IF(E33="休日",MAX(0,$B$6-$B$10),MAX(0,$B$5-$B$9)) -> 8 | G33: =G32+F33 -> 94.5
... A215: =A214+1 -> 46516 | B215: =CHOOSE(WEEKDAY(A215),"日","月","火","水","木","金","土") -> 日 | C215: =IF(OR(WEEKDAY(A215,2)>5,COUNTIF($I$16:$I$35,A215)>0),"休日","平日") -> 休日 | E215: =IF(D215<>"",D215,C215) -> 休日 | F215: =IF(E215="休日",MAX(0,$B$6-$B$10),MAX(0,$B$5-$B$9)) -> 8 | G215: =G214+F215 -> 988
